<?xml version="1.0"?>
<robot xmlns:xacro="http://ros.org/wiki/xacro">
  <xacro:macro name="abb_irb6640_180_255" params="prefix">

    <!-- collision geometry macros -->
    <xacro:include filename="$(find rpi_abb_irb6640_180_255_support)/urdf/irb6640_180_255_base_link_geometry.xacro" />
    <xacro:include filename="$(find rpi_abb_irb6640_180_255_support)/urdf/irb6640_180_255_link_1_geometry.xacro" />
    <xacro:include filename="$(find rpi_abb_irb6640_180_255_support)/urdf/irb6640_180_255_link_2_geometry.xacro" />
    <xacro:include filename="$(find rpi_abb_irb6640_180_255_support)/urdf/irb6640_180_255_link_3_geometry.xacro" />
    <xacro:include filename="$(find rpi_abb_irb6640_180_255_support)/urdf/irb6640_180_255_link_4_geometry.xacro" />
    <xacro:include filename="$(find rpi_abb_irb6640_180_255_support)/urdf/irb6640_180_255_link_5_geometry.xacro" />
    <xacro:include filename="$(find rpi_abb_irb6640_180_255_support)/urdf/irb6640_180_255_link_6_geometry.xacro" />

    <!-- link list -->
    <link name="${prefix}base_link">
      <xacro:base_link_geometry />

      <visual name="visual">
        <geometry>
          <mesh filename="package://rpi_abb_irb6640_180_255_support/meshes/irb6640_180_255/visual/Base.stl"/>
        </geometry>
        <material name="orange">
          <color rgba="1 .42 .04 1"/>
        </material>        
      </visual>

      <xacro:include filename="$(find rpi_abb_irb6640_180_255_support)/urdf/irb6640_180_255_base_link_inertial.xacro" />

    </link>
    <link name="${prefix}link_1">
      <xacro:link_1_geometry />
      <visual name="visual">
        <origin rpi="0 0 0" xyz="0 0 -.78"/>
        <geometry>          
          <mesh filename="package://rpi_abb_irb6640_180_255_support/meshes/irb6640_180_255/visual/Link1.stl"/>          
        </geometry>
        <material name="orange"/>  
      </visual>
      <visual name="visual2">
        <origin rpi="0 0 0" xyz="0 0 -.78"/>
        <geometry>
          <mesh filename="package://rpi_abb_irb6640_180_255_support/meshes/irb6640_180_255/visual/LinkD1.stl"/>
        </geometry>
        <material name="orange"/>         
      </visual>
      <xacro:include filename="$(find rpi_abb_irb6640_180_255_support)/urdf/irb6640_180_255_link_1_inertial.xacro" />
    </link>
    <link name="${prefix}link_2">
      <xacro:link_2_geometry />
      <visual name="visual">
        <origin rpi="0 0 0" xyz="-.32 0 -.78"/>
        <geometry>
          <mesh filename="package://rpi_abb_irb6640_180_255_support/meshes/irb6640_180_255/visual/Link2.stl"/>
        </geometry>
        <material name="orange"/>   
      </visual>
      <xacro:include filename="$(find rpi_abb_irb6640_180_255_support)/urdf/irb6640_180_255_link_2_inertial.xacro" />
    </link>
    <link name="${prefix}link_3">
      <xacro:link_3_geometry />
      <visual name="visual">
        <origin rpi="0 0 0" xyz="-.32 0 -1.855"/>
        <geometry>
          <mesh filename="package://rpi_abb_irb6640_180_255_support/meshes/irb6640_180_255/visual/Link3.stl"/>
        </geometry>
        <material name="orange"/>   
      </visual>
      <xacro:include filename="$(find rpi_abb_irb6640_180_255_support)/urdf/irb6640_180_255_link_3_inertial.xacro" />
    </link>
    <link name="${prefix}link_4">
      <xacro:link_4_geometry />
      <visual name="visual">
        <origin rpi="0 0 0" xyz="-.32 0 -2.055"/>
        <geometry>
          <mesh filename="package://rpi_abb_irb6640_180_255_support/meshes/irb6640_180_255/visual/Link4.stl"/>
        </geometry>
        <material name="orange"/>
      </visual>
      <xacro:include filename="$(find rpi_abb_irb6640_180_255_support)/urdf/irb6640_180_255_link_4_inertial.xacro" />
    </link>
    <link name="${prefix}link_5">
      <xacro:link_5_geometry />
      <visual name="visual">
        <origin rpi="0 0 0" xyz="-1.462 0 -2.055"/>
        <geometry>
          <mesh filename="package://rpi_abb_irb6640_180_255_support/meshes/irb6640_180_255/visual/Link5.stl"/>
        </geometry>
        <material name="orange"/>
      </visual>
      <xacro:include filename="$(find rpi_abb_irb6640_180_255_support)/urdf/irb6640_180_255_link_5_inertial.xacro" />
    </link>
    <link name="${prefix}link_6">
      <xacro:link_6_geometry />
      <visual name="visual">
        <origin rpi="0 0 0" xyz="-1.662 0 -2.055"/>
        <geometry>
          <mesh filename="package://rpi_abb_irb6640_180_255_support/meshes/irb6640_180_255/visual/Link6.stl"/>
        </geometry>
        <material name="orange"/>
      </visual>
      <xacro:include filename="$(find rpi_abb_irb6640_180_255_support)/urdf/irb6640_180_255_link_6_inertial.xacro" />
    </link>
    <link name="${prefix}tool0"/>

    
    <!-- end of link list -->

    <!-- joint list -->
    <joint type="revolute" name="${prefix}joint_1">
      <origin xyz="0 0 0.780" rpy="0 0 0"/>
      <axis xyz="0 0 1"/>
      <parent link="${prefix}base_link"/>
      <child link="${prefix}link_1"/>
      <limit effort="0" lower="-2.967" upper="2.967" velocity="1.7453"/>
    </joint>
    <joint type="revolute" name="${prefix}joint_2">
      <origin xyz="0.320 0 0" rpy="0 0 0"/>
      <axis xyz="0 1 0"/>
      <parent link="${prefix}link_1"/>
      <child link="${prefix}link_2"/>
      <limit effort="0" lower="-1.134" upper="1.4855" velocity="1.5707"/>
    </joint>
    <joint type="revolute" name="${prefix}joint_3">
      <origin xyz="0 0 1.075" rpy="0 0 0"/>
      <axis xyz="0 1 0"/>
      <parent link="${prefix}link_2"/>
      <child link="${prefix}link_3"/>
      <limit effort="0" lower="-3.142" upper="1.222" velocity="1.5707"/>
    </joint>
    <joint type="revolute" name="${prefix}joint_4">
      <origin xyz="0 0 0.2" rpy="0 0 0"/>
      <axis xyz="1 0 0"/>
      <parent link="${prefix}link_3"/>
      <child link="${prefix}link_4"/>
      <limit effort="0" lower="-5.236" upper="5.236" velocity="2.9671"/>
    </joint>
    <joint type="revolute" name="${prefix}joint_5">
      <origin xyz="1.142 0 0 " rpy="0 0 0"/>
      <axis xyz="0 1 0"/>
      <parent link="${prefix}link_4"/>
      <child link="${prefix}link_5"/>
      <limit effort="0" lower="-2.094" upper="2.094" velocity="2.4435"/>
    </joint>
    <joint type="revolute" name="${prefix}joint_6">
      <origin xyz="0.2 0 0 " rpy="0 0 0"/>
      <axis xyz="1 0 0"/>
      <parent link="${prefix}link_5"/>
      <child link="${prefix}link_6"/>
      <limit effort="0" lower="-6.283" upper="6.283" velocity="3.3161"/>
    </joint>
    <joint type="fixed" name="${prefix}joint_6-tool0">
      <parent link="${prefix}link_6"/>
      <child link="${prefix}tool0"/>
      <origin xyz="0 0 0" rpy="0 1.57079632679 0"/>
    </joint>
    
    <!-- end of joint list -->

    <!-- ROS base_link to ABB World Coordinates transform -->
    <link name="${prefix}base" />
    <joint name="${prefix}base_link-base" type="fixed">
      <origin xyz="0 0 0" rpy="0 0 0"/>
      <parent link="${prefix}base_link"/>
      <child link="${prefix}base"/>
    </joint>
  </xacro:macro>
</robot>
